Workbook

Sheet 建议展示
A1: 通用转存演示：金尊分红司庆，以45岁女性为例
A2: 姓名 | C2: 年龄 | D2: 45 | E2: 总保费 | F2: 总额保持一致，逐年进行资产优化，实现收益提升 | T2: 优化: 次年提升160% 第3年提升184% …... 第20年提升255%
A3: 性别 | B3: 女 | C3: 交期 | D3: 8 | E3: 400000
A4: 年度 | B4: 客户年龄 | C4: 一年定存利率 | D4: 0.0095 | F4: 继续存 | I4: 转存利益表 | O4: 万能追加 | Q4: 0.029 | R4: XJHB | T4: 收益提升 | V4: 流动性
C5: 原账户金额 | D5: 当年收益 | E5: 累计收益 | F5: 原账户 | G5: 当年收益 | H5: 累计收益 | I5: 首期 | J5: 保证现价 | K5: 当年红利 | L5: 累计红利 | M5: 累计收益 | N5: 主险生存总利益 | O5: 万能追加 | P5: 当年收益 | Q5: 万能累计收益 | R5: 特别 | S5: 金额 | T5: 合计收益 | U5: 提升幅度 | V5: 总流动 | W5: 流动比率
A6: 1 | B6: =VLOOKUP(A6,贴主险建议书!A:B,2,0) -> 61 | C6: =E3 -> 400000 | D6: =C6*$D$4 -> 3800 | E6: =D6+C6-$C$6 -> 3800 | F6: =C6-O6-I6 -> 100000 | G6: =F6*$D$4 -> 950 | H6: =G6 -> 950 | I6: =IF(A6<=$D$3,$C$6/$D$3*$A6,$C$6) -> 50000 | J6: =VLOOKUP(A6,贴主险建议书!A:E,5,0) -> 11051 | K6: =VLOOKUP(A6,贴主险建议书!A:G,7,0) -> 395 | L6: =VLOOKUP(A6,贴主险建议书!A:H,8,0) -> 395 | M6: =IF((N6-I6)<=L6,L6,N6-I6) -> 395 | N6: =VLOOKUP(A6,贴主险建议书!A:O,15,0) -> 11528 | O6: =I6*5 -> 250000 | P6: =O6*98%*$Q$4-O6*2% -> 2105 | Q6: =P6 -> 2105 | R6: 0 | S6: =R6*I6 -> 0 | T6: =M6+Q6+H6+S6 -> 3450 | U6: =T6/E6 -> 0.90789474 | V6: =N6+S6+Q6+O6+H6+F6 -> 364583 | W6: =V6/$C$6 -> 0.9114575
A7: 2 | B7: =VLOOKUP(A7,贴主险建议书!A:B,2,0) -> 62 | C7: =C6+D6 -> 403800 | D7: =C7*$D$4 -> 3836.1 | E7: =D7+C7-$C$6 -> 7636.1 | F7: =C6-O7-I7 -> 50000 | G7: =(F7+H6)*$D$4 -> 484.025 | H7: =G7+H6 -> 1434.025 | I7: =IF(A7<=$D$3,$C$6/$D$3*$A7,$C$6) -> 100000 | J7: =VLOOKUP(A7,贴主险建议书!A:E,5,0) -> 28025 | K7: =VLOOKUP(A7,贴主险建议书!A:G,7,0) -> 954 | L7: =VLOOKUP(A7,贴主险建议书!A:H,8,0) -> 1349 | M7: =IF((N7-I7)<=L7,L7,N7-I7) -> 1349 | N7: =VLOOKUP(A7,贴主险建议书!A:O,15,0) -> 29462 | O7: =O6 -> 250000 | P7: =(O7+Q6)*$Q$4 -> 7311.045 | Q7: =P7+Q6 -> 9416.045 | R7: 0 | S7: =S6+R7 -> 0 | T7: =M7+Q7+H7+S7 -> 12199.07 | U7: =T7/E7 -> 1.5975524 | V7: =N7+S7+Q7+O7+H7+F7 -> 340312.07 | W7: =V7/$C$6 -> 0.85078018
A8: 3 | B8: =VLOOKUP(A8,贴主险建议书!A:B,2,0) -> 63 | C8: =C7+D7 -> 407636.1 | D8: =C8*$D$4 -> 3872.5429 | E8: =D8+C8-$C$6 -> 11508.643 | F8: 0 | G8: 0 | H8: =H7 -> 1434.025 | I8: =IF(A8<=$D$3,$C$6/$D$3*$A8,$C$6) -> 150000 | J8: =VLOOKUP(A8,贴主险建议书!A:E,5,0) -> 51592 | K8: =VLOOKUP(A8,贴主险建议书!A:G,7,0) -> 1522 | L8: =VLOOKUP(A8,贴主险建议书!A:H,8,0) -> 2871 | M8: =IF((N8-I8)<=L8,L8,N8-I8) -> 2871 | N8: =VLOOKUP(A8,贴主险建议书!A:O,15,0) -> 54562 | O8: =O7 -> 250000 | P8: =(O8+Q7)*$Q$4 -> 7523.0653 | Q8: =P8+Q7 -> 16939.11 | R8: 0 | S8: =S7+R8 -> 0 | T8: =M8+Q8+H8+S8 -> 21244.135 | U8: =T8/E8 -> 1.8459288 | V8: =N8+S8+Q8+O8+H8+F8 -> 322935.14 | W8: =V8/$C$6 -> 0.80733784
A9: 4 | B9: =VLOOKUP(A9,贴主险建议书!A:B,2,0) -> 64 | C9: =C8+D8 -> 411508.64 | D9: =C9*$D$4 -> 3909.3321 | E9: =D9+C9-$C$6 -> 15417.975 | F9: 0 | G9: 0 | H9: =H8 -> 1434.025 | I9: =IF(A9<=$D$3,$C$6/$D$3*$A9,$C$6) -> 200000 | J9: =VLOOKUP(A9,贴主险建议书!A:E,5,0) -> 85924 | K9: =VLOOKUP(A9,贴主险建议书!A:G,7,0) -> 2100 | L9: =VLOOKUP(A9,贴主险建议书!A:H,8,0) -> 4971 | M9: =IF((N9-I9)<=L9,L9,N9-I9) -> 4971 | N9: =VLOOKUP(A9,贴主险建议书!A:O,15,0) -> 91037 | O9: =O8-I6 -> 200000 | P9: =(O9+Q8)*$Q$4-$I$6*1% -> 5791.2342 | Q9: =P9+Q8 -> 22730.345 | R9: 0 | S9: =S8+R9 -> 0 | T9: =M9+Q9+H9+S9 -> 29135.37 | U9: =T9/E9 -> 1.8897014 | V9: =N9+S9+Q9+O9+H9+F9 -> 315201.37 | W9: =V9/$C$6 -> 0.78800342
A10: 5 | B10: =VLOOKUP(A10,贴主险建议书!A:B,2,0) -> 65 | C10: =C9+D9 -> 415417.98 | D10: =C10*$D$4 -> 3946.4708 | E10: =D10+C10-$C$6 -> 19364.446 | F10: 0 | G10: 0 | H10: =H9 -> 1434.025 | I10: =IF(A10<=$D$3,$C$6/$D$3*$A10,$C$6) -> 250000 | J10: =VLOOKUP(A10,贴主险建议书!A:E,5,0) -> 123248 | K10: =VLOOKUP(A10,贴主险建议书!A:G,7,0) -> 2687 | L10: =VLOOKUP(A10,贴主险建议书!A:H,8,0) -> 7658 | M10: =IF((N10-I10)<=L10,L10,N10-I10) -> 7658 | N10: =VLOOKUP(A10,贴主险建议书!A:O,15,0) -> 131143 | O10: =O9-I6 -> 150000 | P10: =(O10+Q9)*$Q$4-$I$6*1% -> 4509.18 | Q10: =P10+Q9 -> 27239.524 | R10: 0 | S10: =S9+R10 -> 0 | T10: =M10+Q10+H10+S10 -> 36331.549 | U10: =T10/E10 -> 1.8761988 | V10: =N10+S10+Q10+O10+H10+F10 -> 309816.55 | W10: =V10/$C$6 -> 0.77454137
A11: 6 | B11: =VLOOKUP(A11,贴主险建议书!A:B,2,0) -> 66 | C11: =C10+D10 -> 419364.45 | D11: =C11*$D$4 -> 3983.9622 | E11: =D11+C11-$C$6 -> 23348.408 | F11: 0 | G11: 0 | H11: =H10 -> 1434.025 | I11: =IF(A11<=$D$3,$C$6/$D$3*$A11,$C$6) -> 300000 | J11: =VLOOKUP(A11,贴主险建议书!A:E,5,0) -> 163662 | K11: =VLOOKUP(A11,贴主险建议书!A:G,7,0) -> 3284 | L11: =VLOOKUP(A11,贴主险建议书!A:H,8,0) -> 10942 | M11: =IF((N11-I11)<=L11,L11,N11-I11) -> 10942 | N11: =VLOOKUP(A11,贴主险建议书!A:O,15,0) -> 175194 | O11: =O10-I6 -> 100000 | P11: =(O11+Q10)*$Q$4+O6*1% -> 6189.9462 | Q11: =P11+Q10 -> 33429.471 | R11: 0 | S11: =S10+R11 -> 0 | T11: =M11+Q11+H11+S11 -> 45805.496 | U11: =T11/E11 -> 1.9618252 | V11: =N11+S11+Q11+O11+H11+F11 -> 310057.5 | W11: =V11/$C$6 -> 0.77514374
A12: 7 | B12: =VLOOKUP(A12,贴主险建议书!A:B,2,0) -> 67 | C12: =C11+D11 -> 423348.41 | D12: =C12*$D$4 -> 4021.8099 | E12: =D12+C12-$C$6 -> 27370.218 | F12: 0 | G12: 0 | H12: =H11 -> 1434.025 | I12: =IF(A12<=$D$3,$C$6/$D$3*$A12,$C$6) -> 350000 | J12: =VLOOKUP(A12,贴主险建议书!A:E,5,0) -> 207325 | K12: =VLOOKUP(A12,贴主险建议书!A:G,7,0) -> 3890 | L12: =VLOOKUP(A12,贴主险建议书!A:H,8,0) -> 14831 | M12: =IF((N12-I12)<=L12,L12,N12-I12) -> 14831 | N12: =VLOOKUP(A12,贴主险建议书!A:O,15,0) -> 223071 | O12: =O11-I6 -> 50000 | P12: =(O12+Q11)*$Q$4 -> 2419.4547 | Q12: =P12+Q11 -> 35848.925 | R12: 0 | S12: =S11+R12 -> 0 | T12: =M12+Q12+H12+S12 -> 52113.95 | U12: =T12/E12 -> 1.9040386 | V12: =N12+S12+Q12+O12+H12+F12 -> 310353.95 | W12: =V12/$C$6 -> 0.77588488
A13: 8 | B13: =VLOOKUP(A13,贴主险建议书!A:B,2,0) -> 68 | C13: =C12+D12 -> 427370.22 | D13: =C13*$D$4 -> 4060.0171 | E13: =D13+C13-$C$6 -> 31430.235 | F13: 0 | G13: 0 | H13: =H12 -> 1434.025 | I13: =IF(A13<=$D$3,$C$6/$D$3*$A13,$C$6) -> 400000 | J13: =VLOOKUP(A13,贴主险建议书!A:E,5,0) -> 254299 | K13: =VLOOKUP(A13,贴主险建议书!A:G,7,0) -> 4505 | L13: =VLOOKUP(A13,贴主险建议书!A:H,8,0) -> 19337 | M13: =IF((N13-I13)<=L13,L13,N13-I13) -> 19337 | N13: =VLOOKUP(A13,贴主险建议书!A:O,15,0) -> 274997 | O13: =$C$6-I13 -> 0 | P13: =(O13+Q12)*$Q$4 -> 1039.6188 | Q13: =P13+Q12 -> 36888.544 | R13: 0 | S13: =S12+R13 -> 0 | T13: =M13+Q13+H13+S13 -> 57659.569 | U13: =T13/E13 -> 1.8345256 | V13: =N13+S13+Q13+O13+H13+F13 -> 313319.57 | W13: =V13/$C$6 -> 0.78329892
A14: 9 | B14: =VLOOKUP(A14,贴主险建议书!A:B,2,0) -> 69 | C14: =C13+D13 -> 431430.24 | D14: =C14*$D$4 -> 4098.5872 | E14: =D14+C14-$C$6 -> 35528.822 | F14: 0 | G14: 0 | H14: =H13 -> 1434.025 | I14: =IF(A14<=$D$3,$C$6/$D$3*$A14,$C$6) -> 400000 | J14: =VLOOKUP(A14,贴主险建议书!A:E,5,0) -> 262707 | K14: =VLOOKUP(A14,贴主险建议书!A:G,7,0) -> 4578 | L14: =VLOOKUP(A14,贴主险建议书!A:H,8,0) -> 23914 | M14: =IF((N14-I14)<=L14,L14,N14-I14) -> 23914 | N14: =VLOOKUP(A14,贴主险建议书!A:O,15,0) -> 288573 | O14: =$C$6-I14 -> 0 | P14: =(O14+Q13)*$Q$4 -> 1069.7678 | Q14: =P14+Q13 -> 37958.312 | R14: 0 | S14: =S13+R14 -> 0 | T14: =M14+Q14+H14+S14 -> 63306.337 | U14: =T14/E14 -> 1.7818304 | V14: =N14+S14+Q14+O14+H14+F14 -> 327965.34 | W14: =V14/$C$6 -> 0.81991334
A15: 10 | B15: =VLOOKUP(A15,贴主险建议书!A:B,2,0) -> 70 | C15: =C14+D14 -> 435528.82 | D15: =C15*$D$4 -> 4137.5238 | E15: =D15+C15-$C$6 -> 39666.346 | F15: 0 | G15: 0 | H15: =H14 -> 1434.025 | I15: =IF(A15<=$D$3,$C$6/$D$3*$A15,$C$6) -> 400000 | J15: =VLOOKUP(A15,贴主险建议书!A:E,5,0) -> 384713 | K15: =VLOOKUP(A15,贴主险建议书!A:G,7,0) -> 4651 | L15: =VLOOKUP(A15,贴主险建议书!A:H,8,0) -> 28565 | M15: =IF((N15-I15)<=L15,L15,N15-I15) -> 28565 | N15: =VLOOKUP(A15,贴主险建议书!A:O,15,0) -> 415969 | O15: =$C$6-I15 -> 0 | P15: =(O15+Q14)*$Q$4 -> 1100.791 | Q15: =P15+Q14 -> 39059.103 | R15: 0 | S15: =S14+R15 -> 0 | T15: =M15+Q15+H15+S15 -> 69058.128 | U15: =T15/E15 -> 1.7409753 | V15: =N15+S15+Q15+O15+H15+F15 -> 456462.13 | W15: =V15/$C$6 -> 1.1411553
A16: 11 | B16: =VLOOKUP(A16,贴主险建议书!A:B,2,0) -> 71 | C16: =C15+D15 -> 439666.35 | D16: =C16*$D$4 -> 4176.8303 | E16: =D16+C16-$C$6 -> 43843.176 | F16: 0 | G16: 0 | H16: =H15 -> 1434.025 | I16: =IF(A16<=$D$3,$C$6/$D$3*$A16,$C$6) -> 400000 | J16: =VLOOKUP(A16,贴主险建议书!A:E,5,0) -> 390828 | K16: =VLOOKUP(A16,贴主险建议书!A:G,7,0) -> 4724 | L16: =VLOOKUP(A16,贴主险建议书!A:H,8,0) -> 33290 | M16: =IF((N16-I16)<=L16,L16,N16-I16) -> 33290 | N16: =VLOOKUP(A16,贴主险建议书!A:O,15,0) -> 427702 | O16: =$C$6-I16 -> 0 | P16: =(O16+Q15)*$Q$4 -> 1132.714 | Q16: =P16+Q15 -> 40191.817 | R16: 0 | S16: =S15+R16 -> 0 | T16: =M16+Q16+H16+S16 -> 74915.842 | U16: =T16/E16 -> 1.708723 | V16: =N16+S16+Q16+O16+H16+F16 -> 469327.84 | W16: =V16/$C$6 -> 1.1733196
A17: 12 | B17: =VLOOKUP(A17,贴主险建议书!A:B,2,0) -> 72 | C17: =C16+D16 -> 443843.18 | D17: =C17*$D$4 -> 4216.5102 | E17: =D17+C17-$C$6 -> 48059.687 | F17: 0 | G17: 0 | H17: =H16 -> 1434.025 | I17: =IF(A17<=$D$3,$C$6/$D$3*$A17,$C$6) -> 400000 | J17: =VLOOKUP(A17,贴主险建议书!A:E,5,0) -> 397038 | K17: =VLOOKUP(A17,贴主险建议书!A:G,7,0) -> 4799 | L17: =VLOOKUP(A17,贴主险建议书!A:H,8,0) -> 38088 | M17: =IF((N17-I17)<=L17,L17,N17-I17) -> 39767 | N17: =VLOOKUP(A17,贴主险建议书!A:O,15,0) -> 439767 | O17: =$C$6-I17 -> 0 | P17: =(O17+Q16)*$Q$4 -> 1165.5627 | Q17: =P17+Q16 -> 41357.38 | R17: 0 | S17: =S16+R17 -> 0 | T17: =M17+Q17+H17+S17 -> 82558.405 | U17: =T17/E17 -> 1.7178307 | V17: =N17+S17+Q17+O17+H17+F17 -> 482558.4 | W17: =V17/$C$6 -> 1.206396
A18: 13 | B18: =VLOOKUP(A18,贴主险建议书!A:B,2,0) -> 73 | C18: =C17+D17 -> 448059.69 | D18: =C18*$D$4 -> 4256.567 | E18: =D18+C18-$C$6 -> 52316.254 | F18: 0 | G18: 0 | H18: =H17 -> 1434.025 | I18: =IF(A18<=$D$3,$C$6/$D$3*$A18,$C$6) -> 400000 | J18: =VLOOKUP(A18,贴主险建议书!A:E,5,0) -> 403280 | K18: =VLOOKUP(A18,贴主险建议书!A:G,7,0) -> 4874 | L18: =VLOOKUP(A18,贴主险建议书!A:H,8,0) -> 42963 | M18: =IF((N18-I18)<=L18,L18,N18-I18) -> 52112 | N18: =VLOOKUP(A18,贴主险建议书!A:O,15,0) -> 452112 | O18: =$C$6-I18 -> 0 | P18: =(O18+Q17)*$Q$4 -> 1199.364 | Q18: =P18+Q17 -> 42556.744 | R18: 0 | S18: =S17+R18 -> 0 | T18: =M18+Q18+H18+S18 -> 96102.769 | U18: =T18/E18 -> 1.8369582 | V18: =N18+S18+Q18+O18+H18+F18 -> 496102.77 | W18: =V18/$C$6 -> 1.2402569
A19: 14 | B19: =VLOOKUP(A19,贴主险建议书!A:B,2,0) -> 74 | C19: =C18+D18 -> 452316.25 | D19: =C19*$D$4 -> 4297.0044 | E19: =D19+C19-$C$6 -> 56613.258 | F19: 0 | G19: 0 | H19: =H18 -> 1434.025 | I19: =IF(A19<=$D$3,$C$6/$D$3*$A19,$C$6) -> 400000 | J19: =VLOOKUP(A19,贴主险建议书!A:E,5,0) -> 409554 | K19: =VLOOKUP(A19,贴主险建议书!A:G,7,0) -> 4950 | L19: =VLOOKUP(A19,贴主险建议书!A:H,8,0) -> 47912 | M19: =IF((N19-I19)<=L19,L19,N19-I19) -> 64747 | N19: =VLOOKUP(A19,贴主险建议书!A:O,15,0) -> 464747 | O19: =$C$6-I19 -> 0 | P19: =(O19+Q18)*$Q$4 -> 1234.1456 | Q19: =P19+Q18 -> 43790.889 | R19: 0 | S19: =S18+R19 -> 0 | T19: =M19+Q19+H19+S19 -> 109971.91 | U19: =T19/E19 -> 1.9425117 | V19: =N19+S19+Q19+O19+H19+F19 -> 509971.91 | W19: =V19/$C$6 -> 1.2749298
A20: 15 | B20: =VLOOKUP(A20,贴主险建议书!A:B,2,0) -> 75 | C20: =C19+D19 -> 456613.26 | D20: =C20*$D$4 -> 4337.826 | E20: =D20+C20-$C$6 -> 60951.084 | F20: 0 | G20: 0 | H20: =H19 -> 1434.025 | I20: =IF(A20<=$D$3,$C$6/$D$3*$A20,$C$6) -> 400000 | J20: =VLOOKUP(A20,贴主险建议书!A:E,5,0) -> 415924 | K20: =VLOOKUP(A20,贴主险建议书!A:G,7,0) -> 5026 | L20: =VLOOKUP(A20,贴主险建议书!A:H,8,0) -> 52939 | M20: =IF((N20-I20)<=L20,L20,N20-I20) -> 77752 | N20: =VLOOKUP(A20,贴主险建议书!A:O,15,0) -> 477752 | O20: =$C$6-I20 -> 0 | P20: =(O20+Q19)*$Q$4 -> 1269.9358 | Q20: =P20+Q19 -> 45060.825 | R20: 0 | S20: =S19+R20 -> 0 | T20: =M20+Q20+H20+S20 -> 124246.85 | U20: =T20/E20 -> 2.0384683 | V20: =N20+S20+Q20+O20+H20+F20 -> 524246.85 | W20: =V20/$C$6 -> 1.3106171
A21: 16 | B21: =VLOOKUP(A21,贴主险建议书!A:B,2,0) -> 76 | C21: =C20+D20 -> 460951.08 | D21: =C21*$D$4 -> 4379.0353 | E21: =D21+C21-$C$6 -> 65330.119 | F21: 0 | G21: 0 | H21: =H20 -> 1434.025 | I21: =IF(A21<=$D$3,$C$6/$D$3*$A21,$C$6) -> 400000 | J21: =VLOOKUP(A21,贴主险建议书!A:E,5,0) -> 422357 | K21: =VLOOKUP(A21,贴主险建议书!A:G,7,0) -> 5103 | L21: =VLOOKUP(A21,贴主险建议书!A:H,8,0) -> 58042 | M21: =IF((N21-I21)<=L21,L21,N21-I21) -> 91112 | N21: =VLOOKUP(A21,贴主险建议书!A:O,15,0) -> 491112 | O21: =$C$6-I21 -> 0 | P21: =(O21+Q20)*$Q$4 -> 1306.7639 | Q21: =P21+Q20 -> 46367.589 | R21: 0 | S21: =S20+R21 -> 0 | T21: =M21+Q21+H21+S21 -> 138913.61 | U21: =T21/E21 -> 2.1263334 | V21: =N21+S21+Q21+O21+H21+F21 -> 538913.61 | W21: =V21/$C$6 -> 1.347284
A22: 17 | B22: =VLOOKUP(A22,贴主险建议书!A:B,2,0) -> 77 | C22: =C21+D21 -> 465330.12 | D22: =C22*$D$4 -> 4420.6361 | E22: =D22+C22-$C$6 -> 69750.755 | F22: 0 | G22: 0 | H22: =H21 -> 1434.025 | I22: =IF(A22<=$D$3,$C$6/$D$3*$A22,$C$6) -> 400000 | J22: =VLOOKUP(A22,贴主险建议书!A:E,5,0) -> 428854 | K22: =VLOOKUP(A22,贴主险建议书!A:G,7,0) -> 5181 | L22: =VLOOKUP(A22,贴主险建议书!A:H,8,0) -> 63223 | M22: =IF((N22-I22)<=L22,L22,N22-I22) -> 104842 | N22: =VLOOKUP(A22,贴主险建议书!A:O,15,0) -> 504842 | O22: =$C$6-I22 -> 0 | P22: =(O22+Q21)*$Q$4 -> 1344.6601 | Q22: =P22+Q21 -> 47712.249 | R22: 0 | S22: =S21+R22 -> 0 | T22: =M22+Q22+H22+S22 -> 153988.27 | U22: =T22/E22 -> 2.2076933 | V22: =N22+S22+Q22+O22+H22+F22 -> 553988.27 | W22: =V22/$C$6 -> 1.3849707
A23: 18 | B23: =VLOOKUP(A23,贴主险建议书!A:B,2,0) -> 78 | C23: =C22+D22 -> 469750.76 | D23: =C23*$D$4 -> 4462.6322 | E23: =D23+C23-$C$6 -> 74213.387 | F23: 0 | G23: 0 | H23: =H22 -> 1434.025 | I23: =IF(A23<=$D$3,$C$6/$D$3*$A23,$C$6) -> 400000 | J23: =VLOOKUP(A23,贴主险建议书!A:E,5,0) -> 435446 | K23: =VLOOKUP(A23,贴主险建议书!A:G,7,0) -> 5260 | L23: =VLOOKUP(A23,贴主险建议书!A:H,8,0) -> 68483 | M23: =IF((N23-I23)<=L23,L23,N23-I23) -> 118973 | N23: =VLOOKUP(A23,贴主险建议书!A:O,15,0) -> 518973 | O23: =$C$6-I23 -> 0 | P23: =(O23+Q22)*$Q$4 -> 1383.6552 | Q23: =P23+Q22 -> 49095.904 | R23: 0 | S23: =S22+R23 -> 0 | T23: =M23+Q23+H23+S23 -> 169502.93 | U23: =T23/E23 -> 2.283994 | V23: =N23+S23+Q23+O23+H23+F23 -> 569502.93 | W23: =V23/$C$6 -> 1.4237573
A24: 19 | B24: =VLOOKUP(A24,贴主险建议书!A:B,2,0) -> 79 | C24: =C23+D23 -> 474213.39 | D24: =C24*$D$4 -> 4505.0272 | E24: =D24+C24-$C$6 -> 78718.415 | F24: 0 | G24: 0 | H24: =H23 -> 1434.025 | I24: =IF(A24<=$D$3,$C$6/$D$3*$A24,$C$6) -> 400000 | J24: =VLOOKUP(A24,贴主险建议书!A:E,5,0) -> 442134 | K24: =VLOOKUP(A24,贴主险建议书!A:G,7,0) -> 5339 | L24: =VLOOKUP(A24,贴主险建议书!A:H,8,0) -> 73822 | M24: =IF((N24-I24)<=L24,L24,N24-I24) -> 133505 | N24: =VLOOKUP(A24,贴主险建议书!A:O,15,0) -> 533505 | O24: =$C$6-I24 -> 0 | P24: =(O24+Q23)*$Q$4 -> 1423.7812 | Q24: =P24+Q23 -> 50519.686 | R24: 0 | S24: =S23+R24 -> 0 | T24: =M24+Q24+H24+S24 -> 185458.71 | U24: =T24/E24 -> 2.3559762 | V24: =N24+S24+Q24+O24+H24+F24 -> 585458.71 | W24: =V24/$C$6 -> 1.4636468
... A70: 65 | B70: =VLOOKUP(A70,贴主险建议书!A:B,2,0) -> #N/A | C70: =C69+D69 -> 732596.23 | D70: =C70*$D$4 -> 6959.6642 | E70: =D70+C70-$C$6 -> 339555.9 | F70: 0 | G70: 0 | H70: =H69 -> 1434.025 | I70: =IF(A70<=$D$3,$C$6/$D$3*$A70,$C$6) -> 400000 | J70: =VLOOKUP(A70,贴主险建议书!A:E,5,0) -> #N/A | K70: =VLOOKUP(A70,贴主险建议书!A:G,7,0) -> #N/A | L70: =VLOOKUP(A70,贴主险建议书!A:H,8,0) -> #N/A | M70: =IF((N70-I70)<=L70,L70,N70-I70) -> #N/A | N70: =VLOOKUP(A70,贴主险建议书!A:O,15,0) -> #N/A | O70: =$C$6-I70 -> 0 | P70: =(O70+Q69)*$Q$4 -> 5303.3526 | Q70: =P70+Q69 -> 188177.58 | R70: 5 | S70: =S69+R70 -> 15 | T70: =M70+Q70+H70+S70 -> #N/A | U70: =T70/E70 -> #N/A | V70: =N70+S70+Q70+O70+H70+F70 -> #N/A | W70: =V70/$C$6 -> #N/A

Sheet 原表
A1: 客户性别 | B1: 女 | C1: 客户年龄 | D1: 40 | E1: 交期 | F1: 8 | G1: 总保费 | H1: 1080000 | I1: 前三年保费由存款支付，后续保费由万能账户转出支付 | O1: 万能账户按当前2.9%结算利率计算，考虑追加及前五年转出费用，不考虑保障成本 | R1: 建议为0，以现场补贴为促成理由
A2: 交期及总保费必填
A3: 年度 | B3: 客户年龄 | C3: 一年定存利率 | D3: 0.0095 | F3: 继续存 | I3: 转存利益表 | O3: 万能追加 | Q3: 0.029 | R3: XJHB | T3: 收益提升 | V3: 流动性
C4: 原账户金额 | D4: 当年收益 | E4: 累计收益 | F4: 原账户 | G4: 当年收益 | H4: 累计收益 | I4: 首期 | J4: 保证现价 | K4: 当年红利 | L4: 累计红利 | M4: 累计增值 | N4: 主险生存总利益 | O4: 万能追加 | P4: 当年收益 | Q4: 万能累计收益 | R4: 特别 | S4: 金额 | T4: 累计收益 | U4: 相对提升幅度 | V4: 总流动 | W4: 流动比率
A5: 1 | B5: =VLOOKUP(A5,贴主险建议书!A:B,2,0) -> 61 | C5: =H1 -> 1080000 | D5: =C5*$D$3 -> 10260 | E5: =D5+C5-$C$5 -> 10260 | F5: =C5-O5-I5 -> 270000 | G5: =F5*$D$3 -> 2565 | H5: =G5 -> 2565 | I5: =IF(A5<=$F$1,$C$5/$F$1*$A5,$C$5) -> 135000 | J5: =VLOOKUP(A5,贴主险建议书!A:E,5,0) -> 11051 | K5: =VLOOKUP(A5,贴主险建议书!A:G,7,0) -> 395 | L5: =VLOOKUP(A5,贴主险建议书!A:H,8,0) -> 395 | M5: =IF((N5-I5)<=L5,L5,N5-I5) -> 395 | N5: =VLOOKUP(A5,贴主险建议书!A:O,15,0) -> 11528 | O5: =I5*5 -> 675000 | P5: =O5*98%*$Q$3-O5*2% -> 5683.5 | Q5: =P5 -> 5683.5 | R5: 0 | S5: =R5*I5 -> 0 | T5: =M5+Q5+H5+S5 -> 8643.5 | U5: =T5/E5 -> 0.84244639 | V5: =N5+S5+Q5+O5+H5+F5 -> 964776.5 | W5: =V5/$C$5 -> 0.89331157
A6: 2 | B6: =VLOOKUP(A6,贴主险建议书!A:B,2,0) -> 62 | C6: =C5+D5 -> 1090260 | D6: =C6*$D$3 -> 10357.47 | E6: =D6+C6-$C$5 -> 20617.47 | F6: =C5-O6-I6 -> 135000 | G6: =(F6+H5)*$D$3 -> 1306.8675 | H6: =G6+H5 -> 3871.8675 | I6: =IF(A6<=$F$1,$C$5/$F$1*$A6,$C$5) -> 270000 | J6: =VLOOKUP(A6,贴主险建议书!A:E,5,0) -> 28025 | K6: =VLOOKUP(A6,贴主险建议书!A:G,7,0) -> 954 | L6: =VLOOKUP(A6,贴主险建议书!A:H,8,0) -> 1349 | M6: =IF((N6-I6)<=L6,L6,N6-I6) -> 1349 | N6: =VLOOKUP(A6,贴主险建议书!A:O,15,0) -> 29462 | O6: =O5 -> 675000 | P6: =(O6+Q5)*$Q$3 -> 19739.822 | Q6: =P6+Q5 -> 25423.322 | R6: 0 | S6: =S5+R6 -> 0 | T6: =M6+Q6+H6+S6 -> 30644.189 | U6: =T6/E6 -> 1.4863215 | V6: =N6+S6+Q6+O6+H6+F6 -> 868757.19 | W6: =V6/$C$5 -> 0.8044048
A7: 3 | B7: =VLOOKUP(A7,贴主险建议书!A:B,2,0) -> 63 | C7: =C6+D6 -> 1100617.5 | D7: =C7*$D$3 -> 10455.866 | E7: =D7+C7-$C$5 -> 31073.336 | F7: 0 | G7: 0 | H7: =H6 -> 3871.8675 | I7: =IF(A7<=$F$1,$C$5/$F$1*$A7,$C$5) -> 405000 | J7: =VLOOKUP(A7,贴主险建议书!A:E,5,0) -> 51592 | K7: =VLOOKUP(A7,贴主险建议书!A:G,7,0) -> 1522 | L7: =VLOOKUP(A7,贴主险建议书!A:H,8,0) -> 2871 | M7: =IF((N7-I7)<=L7,L7,N7-I7) -> 2871 | N7: =VLOOKUP(A7,贴主险建议书!A:O,15,0) -> 54562 | O7: =O6 -> 675000 | P7: =(O7+Q6)*$Q$3 -> 20312.276 | Q7: =P7+Q6 -> 45735.598 | R7: 0 | S7: =S6+R7 -> 0 | T7: =M7+Q7+H7+S7 -> 52478.465 | U7: =T7/E7 -> 1.6888584 | V7: =N7+S7+Q7+O7+H7+F7 -> 779169.47 | W7: =V7/$C$5 -> 0.72145321
A8: 4 | B8: =VLOOKUP(A8,贴主险建议书!A:B,2,0) -> 64 | C8: =C7+D7 -> 1111073.3 | D8: =C8*$D$3 -> 10555.197 | E8: =D8+C8-$C$5 -> 41628.533 | F8: 0 | G8: 0 | H8: =H7 -> 3871.8675 | I8: =IF(A8<=$F$1,$C$5/$F$1*$A8,$C$5) -> 540000 | J8: =VLOOKUP(A8,贴主险建议书!A:E,5,0) -> 85924 | K8: =VLOOKUP(A8,贴主险建议书!A:G,7,0) -> 2100 | L8: =VLOOKUP(A8,贴主险建议书!A:H,8,0) -> 4971 | M8: =IF((N8-I8)<=L8,L8,N8-I8) -> 4971 | N8: =VLOOKUP(A8,贴主险建议书!A:O,15,0) -> 91037 | O8: =O7-I5 -> 540000 | P8: =(O8+Q7)*$Q$3-$I$5*1% -> 15636.332 | Q8: =P8+Q7 -> 61371.93 | R8: 0 | S8: =S7+R8 -> 0 | T8: =M8+Q8+H8+S8 -> 70214.798 | U8: =T8/E8 -> 1.6866988 | V8: =N8+S8+Q8+O8+H8+F8 -> 696280.8 | W8: =V8/$C$5 -> 0.64470444
A9: 5 | B9: =VLOOKUP(A9,贴主险建议书!A:B,2,0) -> 65 | C9: =C8+D8 -> 1121628.5 | D9: =C9*$D$3 -> 10655.471 | E9: =D9+C9-$C$5 -> 52284.004 | F9: 0 | G9: 0 | H9: =H8 -> 3871.8675 | I9: =IF(A9<=$F$1,$C$5/$F$1*$A9,$C$5) -> 675000 | J9: =VLOOKUP(A9,贴主险建议书!A:E,5,0) -> 123248 | K9: =VLOOKUP(A9,贴主险建议书!A:G,7,0) -> 2687 | L9: =VLOOKUP(A9,贴主险建议书!A:H,8,0) -> 7658 | M9: =IF((N9-I9)<=L9,L9,N9-I9) -> 7658 | N9: =VLOOKUP(A9,贴主险建议书!A:O,15,0) -> 131143 | O9: =O8-I5 -> 405000 | P9: =(O9+Q8)*$Q$3-$I$5*1% -> 12174.786 | Q9: =P9+Q8 -> 73546.716 | R9: 0 | S9: =S8+R9 -> 0 | T9: =M9+Q9+H9+S9 -> 85076.584 | U9: =T9/E9 -> 1.627201 | V9: =N9+S9+Q9+O9+H9+F9 -> 613561.58 | W9: =V9/$C$5 -> 0.56811258
A10: 6 | B10: =VLOOKUP(A10,贴主险建议书!A:B,2,0) -> 66 | C10: =C9+D9 -> 1132284 | D10: =C10*$D$3 -> 10756.698 | E10: =D10+C10-$C$5 -> 63040.702 | F10: 0 | G10: 0 | H10: =H9 -> 3871.8675 | I10: =IF(A10<=$F$1,$C$5/$F$1*$A10,$C$5) -> 810000 | J10: =VLOOKUP(A10,贴主险建议书!A:E,5,0) -> 163662 | K10: =VLOOKUP(A10,贴主险建议书!A:G,7,0) -> 3284 | L10: =VLOOKUP(A10,贴主险建议书!A:H,8,0) -> 10942 | M10: =IF((N10-I10)<=L10,L10,N10-I10) -> 10942 | N10: =VLOOKUP(A10,贴主险建议书!A:O,15,0) -> 175194 | O10: =O9-I5 -> 270000 | P10: =(O10+Q9)*$Q$3+O5*1% -> 16712.855 | Q10: =P10+Q9 -> 90259.571 | R10: 0 | S10: =S9+R10 -> 0 | T10: =M10+Q10+H10+S10 -> 105073.44 | U10: =T10/E10 -> 1.6667555 | V10: =N10+S10+Q10+O10+H10+F10 -> 539325.44 | W10: =V10/$C$5 -> 0.49937541
A11: 7 | B11: =VLOOKUP(A11,贴主险建议书!A:B,2,0) -> 67 | C11: =C10+D10 -> 1143040.7 | D11: =C11*$D$3 -> 10858.887 | E11: =D11+C11-$C$5 -> 73899.588 | F11: 0 | G11: 0 | H11: =H10 -> 3871.8675 | I11: =IF(A11<=$F$1,$C$5/$F$1*$A11,$C$5) -> 945000 | J11: =VLOOKUP(A11,贴主险建议书!A:E,5,0) -> 207325 | K11: =VLOOKUP(A11,贴主险建议书!A:G,7,0) -> 3890 | L11: =VLOOKUP(A11,贴主险建议书!A:H,8,0) -> 14831 | M11: =IF((N11-I11)<=L11,L11,N11-I11) -> 14831 | N11: =VLOOKUP(A11,贴主险建议书!A:O,15,0) -> 223071 | O11: =O10-I5 -> 135000 | P11: =(O11+Q10)*$Q$3 -> 6532.5276 | Q11: =P11+Q10 -> 96792.098 | R11: 0 | S11: =S10+R11 -> 0 | T11: =M11+Q11+H11+S11 -> 115494.97 | U11: =T11/E11 -> 1.5628635 | V11: =N11+S11+Q11+O11+H11+F11 -> 458734.97 | W11: =V11/$C$5 -> 0.4247546
A12: 8 | B12: =VLOOKUP(A12,贴主险建议书!A:B,2,0) -> 68 | C12: =C11+D11 -> 1153899.6 | D12: =C12*$D$3 -> 10962.046 | E12: =D12+C12-$C$5 -> 84861.635 | F12: 0 | G12: 0 | H12: =H11 -> 3871.8675 | I12: =IF(A12<=$F$1,$C$5/$F$1*$A12,$C$5) -> 1080000 | J12: =VLOOKUP(A12,贴主险建议书!A:E,5,0) -> 254299 | K12: =VLOOKUP(A12,贴主险建议书!A:G,7,0) -> 4505 | L12: =VLOOKUP(A12,贴主险建议书!A:H,8,0) -> 19337 | M12: =IF((N12-I12)<=L12,L12,N12-I12) -> 19337 | N12: =VLOOKUP(A12,贴主险建议书!A:O,15,0) -> 274997 | O12: =$C$5-I12 -> 0 | P12: =(O12+Q11)*$Q$3 -> 2806.9709 | Q12: =P12+Q11 -> 99599.069 | R12: 0 | S12: =S11+R12 -> 0 | T12: =M12+Q12+H12+S12 -> 122807.94 | U12: =T12/E12 -> 1.447155 | V12: =N12+S12+Q12+O12+H12+F12 -> 378467.94 | W12: =V12/$C$5 -> 0.35043327
A13: 9 | B13: =VLOOKUP(A13,贴主险建议书!A:B,2,0) -> 69 | C13: =C12+D12 -> 1164861.6 | D13: =C13*$D$3 -> 11066.186 | E13: =D13+C13-$C$5 -> 95927.82 | F13: 0 | G13: 0 | H13: =H12 -> 3871.8675 | I13: =IF(A13<=$F$1,$C$5/$F$1*$A13,$C$5) -> 1080000 | J13: =VLOOKUP(A13,贴主险建议书!A:E,5,0) -> 262707 | K13: =VLOOKUP(A13,贴主险建议书!A:G,7,0) -> 4578 | L13: =VLOOKUP(A13,贴主险建议书!A:H,8,0) -> 23914 | M13: =IF((N13-I13)<=L13,L13,N13-I13) -> 23914 | N13: =VLOOKUP(A13,贴主险建议书!A:O,15,0) -> 288573 | O13: =$C$5-I13 -> 0 | P13: =(O13+Q12)*$Q$3 -> 2888.373 | Q13: =P13+Q12 -> 102487.44 | R13: 0 | S13: =S12+R13 -> 0 | T13: =M13+Q13+H13+S13 -> 130273.31 | U13: =T13/E13 -> 1.3580347 | V13: =N13+S13+Q13+O13+H13+F13 -> 394932.31 | W13: =V13/$C$5 -> 0.36567806
A14: 10 | B14: =VLOOKUP(A14,贴主险建议书!A:B,2,0) -> 70 | C14: =C13+D13 -> 1175927.8 | D14: =C14*$D$3 -> 11171.314 | E14: =D14+C14-$C$5 -> 107099.13 | F14: 0 | G14: 0 | H14: =H13 -> 3871.8675 | I14: =IF(A14<=$F$1,$C$5/$F$1*$A14,$C$5) -> 1080000 | J14: =VLOOKUP(A14,贴主险建议书!A:E,5,0) -> 384713 | K14: =VLOOKUP(A14,贴主险建议书!A:G,7,0) -> 4651 | L14: =VLOOKUP(A14,贴主险建议书!A:H,8,0) -> 28565 | M14: =IF((N14-I14)<=L14,L14,N14-I14) -> 28565 | N14: =VLOOKUP(A14,贴主险建议书!A:O,15,0) -> 415969 | O14: =$C$5-I14 -> 0 | P14: =(O14+Q13)*$Q$3 -> 2972.1358 | Q14: =P14+Q13 -> 105459.58 | R14: 0 | S14: =S13+R14 -> 0 | T14: =M14+Q14+H14+S14 -> 137896.45 | U14: =T14/E14 -> 1.2875589 | V14: =N14+S14+Q14+O14+H14+F14 -> 525300.45 | W14: =V14/$C$5 -> 0.4863893
A15: 11 | B15: =VLOOKUP(A15,贴主险建议书!A:B,2,0) -> 71 | C15: =C14+D14 -> 1187099.1 | D15: =C15*$D$3 -> 11277.442 | E15: =D15+C15-$C$5 -> 118376.58 | F15: 0 | G15: 0 | H15: =H14 -> 3871.8675 | I15: =IF(A15<=$F$1,$C$5/$F$1*$A15,$C$5) -> 1080000 | J15: =VLOOKUP(A15,贴主险建议书!A:E,5,0) -> 390828 | K15: =VLOOKUP(A15,贴主险建议书!A:G,7,0) -> 4724 | L15: =VLOOKUP(A15,贴主险建议书!A:H,8,0) -> 33290 | M15: =IF((N15-I15)<=L15,L15,N15-I15) -> 33290 | N15: =VLOOKUP(A15,贴主险建议书!A:O,15,0) -> 427702 | O15: =$C$5-I15 -> 0 | P15: =(O15+Q14)*$Q$3 -> 3058.3278 | Q15: =P15+Q14 -> 108517.91 | R15: 0 | S15: =S14+R15 -> 0 | T15: =M15+Q15+H15+S15 -> 145679.77 | U15: =T15/E15 -> 1.230647 | V15: =N15+S15+Q15+O15+H15+F15 -> 540091.77 | W15: =V15/$C$5 -> 0.50008498
A16: 12 | B16: =VLOOKUP(A16,贴主险建议书!A:B,2,0) -> 72 | C16: =C15+D15 -> 1198376.6 | D16: =C16*$D$3 -> 11384.577 | E16: =D16+C16-$C$5 -> 129761.15 | F16: 0 | G16: 0 | H16: =H15 -> 3871.8675 | I16: =IF(A16<=$F$1,$C$5/$F$1*$A16,$C$5) -> 1080000 | J16: =VLOOKUP(A16,贴主险建议书!A:E,5,0) -> 397038 | K16: =VLOOKUP(A16,贴主险建议书!A:G,7,0) -> 4799 | L16: =VLOOKUP(A16,贴主险建议书!A:H,8,0) -> 38088 | M16: =IF((N16-I16)<=L16,L16,N16-I16) -> 38088 | N16: =VLOOKUP(A16,贴主险建议书!A:O,15,0) -> 439767 | O16: =$C$5-I16 -> 0 | P16: =(O16+Q15)*$Q$3 -> 3147.0193 | Q16: =P16+Q15 -> 111664.93 | R16: 0 | S16: =S15+R16 -> 0 | T16: =M16+Q16+H16+S16 -> 153624.79 | U16: =T16/E16 -> 1.1839043 | V16: =N16+S16+Q16+O16+H16+F16 -> 555303.79 | W16: =V16/$C$5 -> 0.51417018
A17: 13 | B17: =VLOOKUP(A17,贴主险建议书!A:B,2,0) -> 73 | C17: =C16+D16 -> 1209761.2 | D17: =C17*$D$3 -> 11492.731 | E17: =D17+C17-$C$5 -> 141253.88 | F17: 0 | G17: 0 | H17: =H16 -> 3871.8675 | I17: =IF(A17<=$F$1,$C$5/$F$1*$A17,$C$5) -> 1080000 | J17: =VLOOKUP(A17,贴主险建议书!A:E,5,0) -> 403280 | K17: =VLOOKUP(A17,贴主险建议书!A:G,7,0) -> 4874 | L17: =VLOOKUP(A17,贴主险建议书!A:H,8,0) -> 42963 | M17: =IF((N17-I17)<=L17,L17,N17-I17) -> 42963 | N17: =VLOOKUP(A17,贴主险建议书!A:O,15,0) -> 452112 | O17: =$C$5-I17 -> 0 | P17: =(O17+Q16)*$Q$3 -> 3238.2828 | Q17: =P17+Q16 -> 114903.21 | R17: 0 | S17: =S16+R17 -> 0 | T17: =M17+Q17+H17+S17 -> 161738.08 | U17: =T17/E17 -> 1.1450168 | V17: =N17+S17+Q17+O17+H17+F17 -> 570887.08 | W17: =V17/$C$5 -> 0.52859914
A18: 14 | B18: =VLOOKUP(A18,贴主险建议书!A:B,2,0) -> 74 | C18: =C17+D17 -> 1221253.9 | D18: =C18*$D$3 -> 11601.912 | E18: =D18+C18-$C$5 -> 152855.8 | F18: 0 | G18: 0 | H18: =H17 -> 3871.8675 | I18: =IF(A18<=$F$1,$C$5/$F$1*$A18,$C$5) -> 1080000 | J18: =VLOOKUP(A18,贴主险建议书!A:E,5,0) -> 409554 | K18: =VLOOKUP(A18,贴主险建议书!A:G,7,0) -> 4950 | L18: =VLOOKUP(A18,贴主险建议书!A:H,8,0) -> 47912 | M18: =IF((N18-I18)<=L18,L18,N18-I18) -> 47912 | N18: =VLOOKUP(A18,贴主险建议书!A:O,15,0) -> 464747 | O18: =$C$5-I18 -> 0 | P18: =(O18+Q17)*$Q$3 -> 3332.193 | Q18: =P18+Q17 -> 118235.4 | R18: 0 | S18: =S17+R18 -> 0 | T18: =M18+Q18+H18+S18 -> 170019.27 | U18: =T18/E18 -> 1.1122854 | V18: =N18+S18+Q18+O18+H18+F18 -> 586854.27 | W18: =V18/$C$5 -> 0.54338358
A19: 15 | B19: =VLOOKUP(A19,贴主险建议书!A:B,2,0) -> 75 | C19: =C18+D18 -> 1232855.8 | D19: =C19*$D$3 -> 11712.13 | E19: =D19+C19-$C$5 -> 164567.93 | F19: 0 | G19: 0 | H19: =H18 -> 3871.8675 | I19: =IF(A19<=$F$1,$C$5/$F$1*$A19,$C$5) -> 1080000 | J19: =VLOOKUP(A19,贴主险建议书!A:E,5,0) -> 415924 | K19: =VLOOKUP(A19,贴主险建议书!A:G,7,0) -> 5026 | L19: =VLOOKUP(A19,贴主险建议书!A:H,8,0) -> 52939 | M19: =IF((N19-I19)<=L19,L19,N19-I19) -> 52939 | N19: =VLOOKUP(A19,贴主险建议书!A:O,15,0) -> 477752 | O19: =$C$5-I19 -> 0 | P19: =(O19+Q18)*$Q$3 -> 3428.8266 | Q19: =P19+Q18 -> 121664.23 | R19: 0 | S19: =S18+R19 -> 0 | T19: =M19+Q19+H19+S19 -> 178475.1 | U19: =T19/E19 -> 1.0845072 | V19: =N19+S19+Q19+O19+H19+F19 -> 603288.1 | W19: =V19/$C$5 -> 0.55860009
A20: 16 | B20: =VLOOKUP(A20,贴主险建议书!A:B,2,0) -> 76 | C20: =C19+D19 -> 1244567.9 | D20: =C20*$D$3 -> 11823.395 | E20: =D20+C20-$C$5 -> 176391.32 | F20: 0 | G20: 0 | H20: =H19 -> 3871.8675 | I20: =IF(A20<=$F$1,$C$5/$F$1*$A20,$C$5) -> 1080000 | J20: =VLOOKUP(A20,贴主险建议书!A:E,5,0) -> 422357 | K20: =VLOOKUP(A20,贴主险建议书!A:G,7,0) -> 5103 | L20: =VLOOKUP(A20,贴主险建议书!A:H,8,0) -> 58042 | M20: =IF((N20-I20)<=L20,L20,N20-I20) -> 58042 | N20: =VLOOKUP(A20,贴主险建议书!A:O,15,0) -> 491112 | O20: =$C$5-I20 -> 0 | P20: =(O20+Q19)*$Q$3 -> 3528.2626 | Q20: =P20+Q19 -> 125192.49 | R20: 0 | S20: =S19+R20 -> 0 | T20: =M20+Q20+H20+S20 -> 187106.36 | U20: =T20/E20 -> 1.0607458 | V20: =N20+S20+Q20+O20+H20+F20 -> 620176.36 | W20: =V20/$C$5 -> 0.57423737
A21: 17 | B21: =VLOOKUP(A21,贴主险建议书!A:B,2,0) -> 77 | C21: =C20+D20 -> 1256391.3 | D21: =C21*$D$3 -> 11935.718 | E21: =D21+C21-$C$5 -> 188327.04 | F21: 0 | G21: 0 | H21: =H20 -> 3871.8675 | I21: =IF(A21<=$F$1,$C$5/$F$1*$A21,$C$5) -> 1080000 | J21: =VLOOKUP(A21,贴主险建议书!A:E,5,0) -> 428854 | K21: =VLOOKUP(A21,贴主险建议书!A:G,7,0) -> 5181 | L21: =VLOOKUP(A21,贴主险建议书!A:H,8,0) -> 63223 | M21: =IF((N21-I21)<=L21,L21,N21-I21) -> 63223 | N21: =VLOOKUP(A21,贴主险建议书!A:O,15,0) -> 504842 | O21: =$C$5-I21 -> 0 | P21: =(O21+Q20)*$Q$3 -> 3630.5822 | Q21: =P21+Q20 -> 128823.07 | R21: 0 | S21: =S20+R21 -> 0 | T21: =M21+Q21+H21+S21 -> 195917.94 | U21: =T21/E21 -> 1.040307 | V21: =N21+S21+Q21+O21+H21+F21 -> 637536.94 | W21: =V21/$C$5 -> 0.59031198
A22: 18 | B22: =VLOOKUP(A22,贴主险建议书!A:B,2,0) -> 78 | C22: =C21+D21 -> 1268327 | D22: =C22*$D$3 -> 12049.107 | E22: =D22+C22-$C$5 -> 200376.15 | F22: 0 | G22: 0 | H22: =H21 -> 3871.8675 | I22: =IF(A22<=$F$1,$C$5/$F$1*$A22,$C$5) -> 1080000 | J22: =VLOOKUP(A22,贴主险建议书!A:E,5,0) -> 435446 | K22: =VLOOKUP(A22,贴主险建议书!A:G,7,0) -> 5260 | L22: =VLOOKUP(A22,贴主险建议书!A:H,8,0) -> 68483 | M22: =IF((N22-I22)<=L22,L22,N22-I22) -> 68483 | N22: =VLOOKUP(A22,贴主险建议书!A:O,15,0) -> 518973 | O22: =$C$5-I22 -> 0 | P22: =(O22+Q21)*$Q$3 -> 3735.8691 | Q22: =P22+Q21 -> 132558.94 | R22: 0 | S22: =S21+R22 -> 0 | T22: =M22+Q22+H22+S22 -> 204913.81 | U22: =T22/E22 -> 1.0226457 | V22: =N22+S22+Q22+O22+H22+F22 -> 655403.81 | W22: =V22/$C$5 -> 0.60685538
A23: 19 | B23: =VLOOKUP(A23,贴主险建议书!A:B,2,0) -> 79 | C23: =C22+D22 -> 1280376.1 | D23: =C23*$D$3 -> 12163.573 | E23: =D23+C23-$C$5 -> 212539.72 | F23: 0 | G23: 0 | H23: =H22 -> 3871.8675 | I23: =IF(A23<=$F$1,$C$5/$F$1*$A23,$C$5) -> 1080000 | J23: =VLOOKUP(A23,贴主险建议书!A:E,5,0) -> 442134 | K23: =VLOOKUP(A23,贴主险建议书!A:G,7,0) -> 5339 | L23: =VLOOKUP(A23,贴主险建议书!A:H,8,0) -> 73822 | M23: =IF((N23-I23)<=L23,L23,N23-I23) -> 73822 | N23: =VLOOKUP(A23,贴主险建议书!A:O,15,0) -> 533505 | O23: =$C$5-I23 -> 0 | P23: =(O23+Q22)*$Q$3 -> 3844.2093 | Q23: =P23+Q22 -> 136403.15 | R23: 0 | S23: =S22+R23 -> 0 | T23: =M23+Q23+H23+S23 -> 214097.02 | U23: =T23/E23 -> 1.0073271 | V23: =N23+S23+Q23+O23+H23+F23 -> 673780.02 | W23: =V23/$C$5 -> 0.62387039
... A69: 65 | B69: =VLOOKUP(A69,贴主险建议书!A:B,2,0) -> #N/A | C69: =C68+D68 -> 1978009.8 | D69: =C69*$D$3 -> 18791.093 | E69: =D69+C69-$C$5 -> 916800.92 | F69: 0 | G69: 0 | H69: =H68 -> 3871.8675 | I69: =IF(A69<=$F$1,$C$5/$F$1*$A69,$C$5) -> 1080000 | J69: =VLOOKUP(A69,贴主险建议书!A:E,5,0) -> #N/A | K69: =VLOOKUP(A69,贴主险建议书!A:G,7,0) -> #N/A | L69: =VLOOKUP(A69,贴主险建议书!A:H,8,0) -> #N/A | M69: =IF((N69-I69)<=L69,L69,N69-I69) -> #N/A | N69: =VLOOKUP(A69,贴主险建议书!A:O,15,0) -> #N/A | O69: =$C$5-I69 -> 0 | P69: =(O69+Q68)*$Q$3 -> 14319.052 | Q69: =P69+Q68 -> 508079.46 | R69: 5 | S69: =S68+R69 -> 15 | T69: =M69+Q69+H69+S69 -> #N/A | U69: =T69/E69 -> #N/A | V69: =N69+S69+Q69+O69+H69+F69 -> #N/A | W69: =V69/$C$5 -> #N/A
A70: 66 | B70: =VLOOKUP(A70,贴主险建议书!A:B,2,0) -> #N/A
A71: 67 | B71: =VLOOKUP(A71,贴主险建议书!A:B,2,0) -> #N/A
A72: 68 | B72: =VLOOKUP(A72,贴主险建议书!A:B,2,0) -> #N/A
A73: 69 | B73: =VLOOKUP(A73,贴主险建议书!A:B,2,0) -> #N/A
A74: 70 | B74: =VLOOKUP(A74,贴主险建议书!A:B,2,0) -> #N/A
A75: 71 | B75: =VLOOKUP(A75,贴主险建议书!A:B,2,0) -> #N/A
A76: 72 | B76: =VLOOKUP(A76,贴主险建议书!A:B,2,0) -> #N/A
A77: 73 | B77: =VLOOKUP(A77,贴主险建议书!A:B,2,0) -> #N/A
A78: 74 | B78: =VLOOKUP(A78,贴主险建议书!A:B,2,0) -> #N/A
A79: 75 | B79: =VLOOKUP(A79,贴主险建议书!A:B,2,0) -> #N/A
A80: 76 | B80: =VLOOKUP(A80,贴主险建议书!A:B,2,0) -> #N/A
A81: 77 | B81: =VLOOKUP(A81,贴主险建议书!A:B,2,0) -> #N/A
... A109: 105 | B109: =VLOOKUP(A109,贴主险建议书!A:B,2,0) -> #N/A

Sheet 贴主险建议书
A1: 分红：红利利益演示 万能：万能账户3%结算利益演示（利益演示共4种情形，本演示为其中一种）
A2: 保单年度 | B2: 被保险人年龄 | C2: 期交保费 | D2: 累计保费 | E2: 金尊分红司庆 | I2: 招财宝26 | O2: 组合利益
E3: 现金价值 （退保金） | F3: 身故保险金 | G3: 当年红利 （转入万能 账户） | H3: 累计红利 | I3: 趸交及追加 保费 | J3: 趸交及追加 保费初始费 用 | K3: 当年转入保费 | L3: 当年进入万 能账户价值 | M3: 万能账户价值 | N3: 身故保险金 | O3: 生存总利益 | P3: 生存总利益 增长率（%） | Q3: 身故总利益
I4: 累计趸交及 追加保费 | J4: 保单持续奖励 | K4: 转入保费初 始费用 | L4: 保障成本 | M4: 现金价值
A5: 1 | B5: 61 | C5: 50000 | D5: 50100 | E5: 11051 | F5: 70000 | G5: 395 | H5: 395 | I5: 100 | J5: 2 | K5: 395 | L5: 489 | M5: 492 | N5: 140 | O5: 11528 | P5: -- | Q5: 70140
I6: 100 | J6: 0 | K6: 4 | L6: 0 | M6: 477
A7: 2 | B7: 62 | C7: 50000 | D7: 100100 | E7: 28025 | F7: 120000 | G7: 954 | H7: 1349 | I7: 0 | J7: 0 | K7: 954 | L7: 944 | M7: 1451 | N7: 594 | O7: 29462 | P7: 155.56 | Q7: 120594
I8: 100 | J8: 0 | K8: 10 | L8: 0 | M8: 1436
A9: 3 | B9: 63 | C9: 50000 | D9: 150100 | E9: 51592 | F9: 180000 | G9: 1522 | H9: 2871 | I9: 0 | J9: 0 | K9: 1522 | L9: 1507 | M9: 3000 | N9: 1739 | O9: 54562 | P9: 85.2 | Q9: 181739
I10: 100 | J10: 0 | K10: 15 | L10: 1 | M10: 2970
A11: 4 | B11: 64 | C11: 50000 | D11: 200100 | E11: 85924 | F11: 240000 | G11: 2100 | H11: 4971 | I11: 0 | J11: 0 | K11: 2100 | L11: 2079 | M11: 5165 | N11: 3566 | O11: 91037 | P11: 66.85 | Q11: 243566
I12: 100 | J12: 0 | K12: 21 | L12: 3 | M12: 5114
A13: 5 | B13: 65 | C13: 50000 | D13: 250100 | E13: 123248 | F13: 300000 | G13: 2687 | H13: 7658 | I13: 0 | J13: 0 | K13: 2687 | L13: 2660 | M13: 7974 | N13: 6085 | O13: 131143 | P13: 44.05 | Q13: 306085
I14: 100 | J14: 0 | K14: 27 | L14: 6 | M14: 7894
A15: 6 | B15: 66 | C15: 50000 | D15: 300100 | E15: 163662 | F15: 360000 | G15: 3284 | H15: 10942 | I15: 0 | J15: 0 | K15: 3284 | L15: 3328 | M15: 11532 | N15: 9310 | O15: 175194 | P15: 33.59 | Q15: 369310
I16: 100 | J16: 78 | K16: 33 | L16: 10 | M16: 11532
A17: 7 | B17: 67 | C17: 50000 | D17: 350100 | E17: 207325 | F17: 420000 | G17: 3890 | H17: 14831 | I17: 0 | J17: 0 | K17: 3890 | L17: 3884 | M17: 15747 | N17: 13250 | O17: 223071 | P17: 27.33 | Q17: 433250
I18: 100 | J18: 33 | K18: 39 | L18: 14 | M18: 15747
A19: 8 | B19: 68 | C19: 50000 | D19: 400100 | E19: 254299 | F19: 480000 | G19: 4505 | H19: 19337 | I19: 0 | J19: 0 | K19: 4505 | L19: 4499 | M19: 20697 | N19: 17918 | O19: 274997 | P19: 23.28 | Q19: 497918
I20: 100 | J20: 39 | K20: 45 | L20: 21 | M20: 20697
A21: 9 | B21: 69 | C21: 0 | D21: 400100 | E21: 262707 | F21: 480000 | G21: 4578 | H21: 23914 | I21: 0 | J21: 0 | K21: 4578 | L21: 4577 | M21: 25866 | N21: 23324 | O21: 288573 | P21: 4.94 | Q21: 503324
I22: 100 | J22: 45 | K22: 46 | L22: 28 | M22: 25866
A23: 10 | B23: 70 | C23: 0 | D23: 400100 | E23: 384713 | F23: 480000 | G23: 4651 | H23: 28565 | I23: 0 | J23: 0 | K23: 4651 | L23: 4650 | M23: 31256 | N23: 28817 | O23: 415969 | P23: 44.15 | Q23: 508817
I24: 100 | J24: 46 | K24: 47 | L24: 36 | M24: 31256
A25: 11 | B25: 71 | C25: 0 | D25: 400100 | E25: 390828 | F25: 480000 | G25: 4724 | H25: 33290 | I25: 0 | J25: 0 | K25: 4724 | L25: 4724 | M25: 36874 | N25: 34398 | O25: 427702 | P25: 2.82 | Q25: 514398
I26: 100 | J26: 47 | K26: 47 | L26: 43 | M26: 36874
A27: 12 | B27: 72 | C27: 0 | D27: 400100 | E27: 397038 | F27: 480000 | G27: 4799 | H27: 38088 | I27: 0 | J27: 0 | K27: 4799 | L27: 4798 | M27: 42729 | N27: 40067 | O27: 439767 | P27: 2.82 | Q27: 520067
I28: 100 | J28: 47 | K28: 48 | L28: 49 | M28: 42729
A29: 13 | B29: 73 | C29: 0 | D29: 400100 | E29: 403280 | F29: 480000 | G29: 4874 | H29: 42963 | I29: 0 | J29: 0 | K29: 4874 | L29: 4873 | M29: 48831 | N29: 45826 | O29: 452112 | P29: 2.81 | Q29: 525826
I30: 100 | J30: 48 | K30: 49 | L30: 52 | M30: 48831
A31: 14 | B31: 74 | C31: 0 | D31: 400100 | E31: 409554 | F31: 480000 | G31: 4950 | H31: 47912 | I31: 0 | J31: 0 | K31: 4950 | L31: 4949 | M31: 55193 | N31: 51675 | O31: 464747 | P31: 2.79 | Q31: 531675
I32: 100 | J32: 49 | K32: 50 | L32: 51 | M32: 55193
A33: 郑重声明：本保险产品计划单位为人民币元，假定被保险人为标准体，所列产品、费率、基本保险金额等与保险合同不一定一致，有关产品细责 及权利、义务、责任免除等事宜的说明、解释、承诺或保证等，请以保险合同为准。 本保险产品计划标识号为 W(002)-ABCDCA-946A06-6C7649-5D9918-709EC4-238ECA 9/25
A34: 苏女士 平安保险产品计划 代理人：农桂婷 业务员代码：1142360973
A35: 保单年度 | B35: 被保险人年 龄 | C35: 期交保费 | D35: 累计保费 | E35: 金尊分红司庆 | I35: 招财宝26 | O35: 组合利益
E36: 现金价值 （退保金） | F36: 身故保险金 | G36: 当年红利 （转入万能 账户） | H36: 累计红利 | I36: 趸交及追加 保费 | J36: 趸交及追加 保费初始费 用 | K36: 当年转入保 费 | L36: 当年进入万 能账户价值 | M36: 万能账户价 值 | N36: 身故保险金 | O36: 生存总利益 | P36: 生存总利益 增长率（%） | Q36: 身故总利益
I37: 累计趸交及 追加保费 | J37: 保单持续奖 励 | K37: 转入保费初 始费用 | L37: 保障成本 | M37: 现金价值
A38: 15 | B38: 75 | C38: 0 | D38: 400100 | E38: 415924 | F38: 480000 | G38: 5026 | H38: 52939 | I38: 0 | J38: 0 | K38: 5026 | L38: 5025 | M38: 61829 | N38: 57615 | O38: 477752 | P38: 2.8 | Q38: 537615
I39: 100 | J39: 50 | K39: 50 | L39: 45 | M39: 61829
A40: 16 | B40: 76 | C40: 0 | D40: 400100 | E40: 422357 | F40: 480000 | G40: 5103 | H40: 58042 | I40: 0 | J40: 0 | K40: 5103 | L40: 5103 | M40: 68756 | N40: 63653 | O40: 491112 | P40: 2.8 | Q40: 543653
...
